2013-03-15 08:49:00,806 - ubuntuone.SyncDaemon.Main - INFO - Starting Ubuntu One client version 4.0.0
2013-03-15 08:49:00,806 - ubuntuone.SyncDaemon.Main - INFO - Using '/home/ilu/Ubuntu One' as root dir
2013-03-15 08:49:00,806 - ubuntuone.SyncDaemon.Main - INFO - Using '/home/ilu/.local/share/ubuntuone/syncdaemon' as data dir
2013-03-15 08:49:00,806 - ubuntuone.SyncDaemon.Main - INFO - Using '/home/ilu/.local/share/ubuntuone/shares' as shares root dir
2013-03-15 08:49:00,807 - ubuntuone.SyncDaemon.tritcask - INFO - Initializing Tritcask on: /home/ilu/.local/share/ubuntuone/syncdaemon/tritcask
2013-03-15 08:49:00,828 - ubuntuone.SyncDaemon.tritcask - INFO - found 1 data files, 0 dead and 0 broken files
2013-03-15 08:49:00,851 - ubuntuone.SyncDaemon.tritcask - INFO - keydir ready! (keys: 2)
2013-03-15 08:49:00,917 - ubuntuone.SyncDaemon.fsm - INFO - loading updated metadata
2013-03-15 08:49:00,917 - ubuntuone.SyncDaemon.fsm - INFO - initialized: idx_path: 1, idx_node_id: 0, shares: 1
2013-03-15 08:49:00,922 - ubuntuone.SyncDaemon.filesystem_notifications.GeneralProcessor - INFO - Ignoring files: ['\\A#.*\\Z', '\\A.*~\\Z', '\\A.*\\.py[oc]\\Z', '\\A.*\\.sw[nopx]\\Z', '\\A.*\\.swpx\\Z', '\\A\\..*\\.tmp\\Z', '\\A\\.~lock\\..*#\\Z', '\\A\\.goutputstream-.*\\Z', '\\A.*-Spotlight\\Z', '\\A\\.DS_Store\\Z']
2013-03-15 08:49:00,931 - ubuntuone.SyncDaemon.TunnelRunner - INFO - Proxy support not installed.
2013-03-15 08:49:00,933 - ubuntuone.SyncDaemon.HQ - INFO - HashQueue: _hasher started
2013-03-15 08:49:01,422 - ubuntuone.SyncDaemon.DBus - INFO - DBusInterface initialized.
2013-03-15 08:49:01,423 - ubuntuone.SyncDaemon.InteractionInterfaces - INFO - connect: args (<ubuntuone.syncdaemon.interaction_interfaces.SyncdaemonService object at 0xaa065ac>,), kwargs {'autoconnecting': True}.
2013-03-15 08:49:01,423 - ubuntuone.SyncDaemon.InteractionInterfaces - INFO - connect: result <generator object connect at 0xaa095cc>.
2013-03-15 08:49:01,844 - ubuntuone.SyncDaemon.Main - NOTE - ---- MARK (state: <State: 'INIT'  (queues IDLE  connection 'Not User Not Network')>; queue: 0; offloaded: 0; hash: 0) ----
2013-03-15 08:49:01,844 - ubuntuone.SyncDaemon.Main - NOTE - Local rescan starting...
2013-03-15 08:49:01,844 - ubuntuone.SyncDaemon.local_rescan - INFO - start scan all volumes
2013-03-15 08:49:01,894 - ubuntuone.SyncDaemon.local_rescan - INFO - processing trash
2013-03-15 08:49:01,895 - ubuntuone.SyncDaemon.local_rescan - INFO - processing move limbo
2013-03-15 08:49:01,895 - ubuntuone.SyncDaemon.InteractionInterfaces - INFO - start: args (<ubuntuone.syncdaemon.interaction_interfaces.SyncdaemonService object at 0xaa065ac>,), kwargs {}.
2013-03-15 08:49:01,895 - ubuntuone.SyncDaemon.InteractionInterfaces - INFO - start: result <Deferred at 0xaa8cdec current result: None>.
2013-03-15 08:49:01,895 - ubuntuone.SyncDaemon - INFO - not starting twisted.manhole
2013-03-15 08:49:01,898 - ubuntuone.SyncDaemon.local_rescan - INFO - Ignoring path as it's a symlink: '/home/ilu/Ubuntu One/Shared With Me'
2013-03-15 08:49:01,898 - ubuntuone.SyncDaemon.Main - NOTE - Local rescan finished!
2013-03-15 08:49:01,899 - ubuntuone.SyncDaemon.Main - INFO - hash queue empty. We are ready!
2013-03-15 08:49:02,712 - twisted - ERROR - Unhandled error in Deferred:
2013-03-15 08:49:02,859 - twisted - ERROR - Unhandled Error
Traceback (most recent call last):
  File "/usr/lib/python2.7/dist-packages/twisted/internet/defer.py", line 368, in callback
    self._startRunCallbacks(result)
  File "/usr/lib/python2.7/dist-packages/twisted/internet/defer.py", line 464, in _startRunCallbacks
    self._runCallbacks()
  File "/usr/lib/python2.7/dist-packages/twisted/internet/defer.py", line 551, in _runCallbacks
    current.result = callback(current.result, *args, **kw)
  File "/usr/lib/python2.7/dist-packages/twisted/internet/defer.py", line 1101, in gotResult
    _inlineCallbacks(r, g, deferred)
--- <exception caught here> ---
  File "/usr/lib/python2.7/dist-packages/twisted/internet/defer.py", line 1045, in _inlineCallbacks
    result = g.send(result)
  File "/usr/lib/python2.7/dist-packages/ubuntuone-client/ubuntuone/syncdaemon/interaction_interfaces.py", line 1266, in connect
    raise NoAccessToken("got empty credentials.")
ubuntuone.syncdaemon.interaction_interfaces.NoAccessToken: got empty credentials.

2013-03-15 09:04:01,844 - ubuntuone.SyncDaemon.Main - NOTE - ---- MARK (state: <State: 'READY'  (queues IDLE  connection 'Not User With Network')>; queue: 0; offloaded: 0; hash: 0) ----
2013-03-15 09:19:01,847 - ubuntuone.SyncDaemon.Main - NOTE - ---- MARK (state: <State: 'READY'  (queues IDLE  connection 'Not User Not Network')>; queue: 0; offloaded: 0; hash: 0) ----
